<robot xmlns:sensor="http://playerstage.sourceforge.net/gazebo/xmlschema/#sensor"
       xmlns:controller="http://playerstage.sourceforge.net/gazebo/xmlschema/#controller"
       xmlns:interface="http://playerstage.sourceforge.net/gazebo/xmlschema/#interface"
       xmlns:xacro="http://www.ros.org/wiki/xacro"
       name="shadowhand_motor">

<!-- Modified version of Shadow's shadowhand_motor_base.urdf.xacro including a dummy base link-->

  <include filename="$(find sr_hand)/model/materials.urdf.xacro" />
  <include filename="$(find sr_hand)/model/hand_urdf/full_hand_motor.urdf.xacro" />
  <include filename="$(find sr_hand)/model/gazebo/gazebo.urdf.xacro" />

 <link name="base_link">
    <inertial>
      <origin xyz="0 0 0"/>
      <mass value="100.0"/>
      <inertia ixx="1.0" ixy="0.0" ixz="0.0" iyy="0.0" iyz="0.0" izz="0.0"/>
    </inertial>
    <visual>
      <origin rpy="0 0 0" xyz="0 0 0.5"/>
      <geometry name="base_link_visual">
        <sphere radius="0.5"/>
      </geometry>
      <material name="Green"/>
    </visual>
  </link>
  <gazebo reference="base_link">
     <material>Gazebo/Green</material>
     <selfCollide>false</selfCollide>
     <static>true</static>
     <turnGravityOff>true</turnGravityOff>
  </gazebo>

  <joint name="base_forearm" type="floating">
    <parent link="base_link"/>
    <child link="forearm_motor"/>
    <origin rpy="0 0 0" xyz="0 0 0"/>
  </joint>


  <xacro:shadowhand_motor>
  </xacro:shadowhand_motor>


</robot>
